Workbook

Sheet Dashboard
H2: ⚠️ 商品驗證 即將到期（90天內）
H3: 證書編號 | J3: 有效日期 | K3: 剩餘天數 | L3: 證書編號 | N3: 有效日期 | O3: 剩餘天數
H4: =IFERROR(到期清單!A3,"") -> CI3A2261861837 | J4: =IF(IFERROR(到期清單!B3,0)=0,"",到期清單!B3) -> 46187 | K4: =IFERROR(到期清單!C3,"") -> 23 | L4: =IFERROR(到期清單!A12,"") -> 0 | N4: =IF(IFERROR(到期清單!B18,0)=0,"",到期清單!B18) | O4: =IFERROR(到期清單!C12,"") -> 0
H5: =IFERROR(到期清單!A4,"") -> CI3A2261861848 | J5: =IF(IFERROR(到期清單!B4,0)=0,"",到期清單!B4) -> 46192 | K5: =IFERROR(到期清單!C4,"") -> 28 | L5: =IFERROR(到期清單!A13,"") -> 0 | N5: =IF(IFERROR(到期清單!B19,0)=0,"",到期清單!B19) | O5: =IFERROR(到期清單!C13,"") -> 0
H6: =IFERROR(到期清單!A5,"") -> CI3A2261861890 | J6: =IF(IFERROR(到期清單!B5,0)=0,"",到期清單!B5) -> 46227 | K6: =IFERROR(到期清單!C5,"") -> 63 | L6: =IFERROR(到期清單!A14,"") -> 0 | N6: =IF(IFERROR(到期清單!B20,0)=0,"",到期清單!B20) | O6: =IFERROR(到期清單!C14,"") -> 0
H7: =IFERROR(到期清單!A6,"") -> CI3A9261861510 | J7: =IF(IFERROR(到期清單!B6,0)=0,"",到期清單!B6) -> 46195 | K7: =IFERROR(到期清單!C6,"") -> 31 | L7: =IFERROR(到期清單!A15,"") -> 0 | N7: =IF(IFERROR(到期清單!B21,0)=0,"",到期清單!B21) | O7: =IFERROR(到期清單!C15,"") -> 0
E8: =圖表資料!B9 -> 66 | F8: 張 | H8: =IFERROR(到期清單!A7,"") -> CI3A2261861917 | J8: =IF(IFERROR(到期清單!B7,0)=0,"",到期清單!B7) -> 46235 | K8: =IFERROR(到期清單!C7,"") -> 71 | L8: =IFERROR(到期清單!A16,"") -> 0 | N8: =IF(IFERROR(到期清單!B22,0)=0,"",到期清單!B22) | O8: =IFERROR(到期清單!C16,"") -> 0
H9: =IFERROR(到期清單!A8,"") -> CI3A2261861928 | J9: =IF(IFERROR(到期清單!B8,0)=0,"",到期清單!B8) -> 46241 | K9: =IFERROR(到期清單!C8,"") -> 77 | L9: =IFERROR(到期清單!A17,"") -> 0 | N9: =IF(IFERROR(到期清單!B23,0)=0,"",到期清單!B23) | O9: =IFERROR(到期清單!C17,"") -> 0
H10: =IFERROR(到期清單!A9,"") -> 0 | J10: =IF(IFERROR(到期清單!B9,0)=0,"",到期清單!B9) | K10: =IFERROR(到期清單!C9,"") -> 0 | L10: =IFERROR(到期清單!A18,"") -> 0 | N10: =IF(IFERROR(到期清單!B24,0)=0,"",到期清單!B24) | O10: =IFERROR(到期清單!C18,"") -> 0
H11: =IFERROR(到期清單!A10,"") -> 0 | J11: =IF(IFERROR(到期清單!B10,0)=0,"",到期清單!B10) | K11: =IFERROR(到期清單!C10,"") -> 0 | L11: =IFERROR(到期清單!A19,"") -> 0 | N11: =IF(IFERROR(到期清單!B25,0)=0,"",到期清單!B25) | O11: =IFERROR(到期清單!C19,"") -> 0
H12: =IFERROR(到期清單!A11,"") -> 0 | J12: =IF(IFERROR(到期清單!B11,0)=0,"",到期清單!B11) | K12: =IFERROR(到期清單!C11,"") -> 0 | L12: =IFERROR(到期清單!A20,"") -> 0 | N12: =IF(IFERROR(到期清單!B26,0)=0,"",到期清單!B26) | O12: =IFERROR(到期清單!C20,"") -> 0
H13: ▶ 刷新到期清單
H16: ⚠️ 節能標章 即將到期（90天內）
H17: 證書編號 | J17: 有效日期 | K17: 剩餘天數 | L17: 證書編號 | N17: 有效日期 | O17: 剩餘天數
H18: =IFERROR(到期清單!F3,"") -> 1110286 | J18: =IF(IFERROR(到期清單!G3,0)=0,"",到期清單!G3) -> 46165 | K18: =IFERROR(到期清單!H3,"") -> 1 | L18: =IFERROR(到期清單!F12,"") -> 0 | N18: =IF(IFERROR(到期清單!K3,0)=0,"",到期清單!K3) | O18: =IFERROR(到期清單!H12,"") -> 0
H19: =IFERROR(到期清單!F4,"") -> 0 | J19: =IF(IFERROR(到期清單!G4,0)=0,"",到期清單!G4) | K19: =IFERROR(到期清單!H4,"") -> 0 | L19: =IFERROR(到期清單!F13,"") -> 0 | N19: =IF(IFERROR(到期清單!K4,0)=0,"",到期清單!K4) | O19: =IFERROR(到期清單!H13,"") -> 0
H20: =IFERROR(到期清單!F5,"") -> 0 | J20: =IF(IFERROR(到期清單!G5,0)=0,"",到期清單!G5) | K20: =IFERROR(到期清單!H5,"") -> 0 | L20: =IFERROR(到期清單!F14,"") -> 0 | N20: =IF(IFERROR(到期清單!K5,0)=0,"",到期清單!K5) | O20: =IFERROR(到期清單!H14,"") -> 0
H21: =IFERROR(到期清單!F6,"") -> 0 | J21: =IF(IFERROR(到期清單!G6,0)=0,"",到期清單!G6) | K21: =IFERROR(到期清單!H6,"") -> 0 | L21: =IFERROR(到期清單!F15,"") -> 0 | N21: =IF(IFERROR(到期清單!K6,0)=0,"",到期清單!K6) | O21: =IFERROR(到期清單!H15,"") -> 0
E22: =圖表資料!E9 -> 31 | F22: 張 | H22: =IFERROR(到期清單!F7,"") -> 0 | J22: =IF(IFERROR(到期清單!G7,0)=0,"",到期清單!G7) | K22: =IFERROR(到期清單!H7,"") -> 0 | L22: =IFERROR(到期清單!F16,"") -> 0 | N22: =IF(IFERROR(到期清單!K7,0)=0,"",到期清單!K7) | O22: =IFERROR(到期清單!H16,"") -> 0
H23: =IFERROR(到期清單!F8,"") -> 0 | J23: =IF(IFERROR(到期清單!G8,0)=0,"",到期清單!G8) | K23: =IFERROR(到期清單!H8,"") -> 0 | L23: =IFERROR(到期清單!F17,"") -> 0 | N23: =IF(IFERROR(到期清單!K8,0)=0,"",到期清單!K8) | O23: =IFERROR(到期清單!H17,"") -> 0
H24: =IFERROR(到期清單!F9,"") -> 0 | J24: =IF(IFERROR(到期清單!G9,0)=0,"",到期清單!G9) | K24: =IFERROR(到期清單!H9,"") -> 0 | L24: =IFERROR(到期清單!F18,"") -> 0 | N24: =IF(IFERROR(到期清單!K9,0)=0,"",到期清單!K9) | O24: =IFERROR(到期清單!H18,"") -> 0
H25: =IFERROR(到期清單!F10,"") -> 0 | J25: =IF(IFERROR(到期清單!G10,0)=0,"",到期清單!G10) | K25: =IFERROR(到期清單!H10,"") -> 0 | L25: =IFERROR(到期清單!F19,"") -> 0 | N25: =IF(IFERROR(到期清單!K10,0)=0,"",到期清單!K10) | O25: =IFERROR(到期清單!H19,"") -> 0
H26: =IFERROR(到期清單!F11,"") -> 0 | J26: =IF(IFERROR(到期清單!G11,0)=0,"",到期清單!G11) | K26: =IFERROR(到期清單!H11,"") -> 0 | L26: =IFERROR(到期清單!F20,"") -> 0 | N26: =IF(IFERROR(到期清單!K11,0)=0,"",到期清單!K11) | O26: =IFERROR(到期清單!H20,"") -> 0
E36: =圖表資料!J33 -> 0.69672131

Sheet 工作表1
A1: 實驗室 | B1: 類別 | C1: 室外機型號 | D1: 測試搭配 (無風管內機型號) | E1: 核備 | F1: 商品驗證登錄證書編號 | G1: 證書有效 期限 | H1: 2027年 年費 | I1: 已展延 | J1: 分類 | K1: 計算用 | L1: 計算用 | M1: 計算用 | N1: 安規測試 報告編號 | O1: 室外機型號 | P1: 額定冷氣能力(kW) | R1: 中間冷氣能力(kW) | T1: 額定消耗功率(W) | V1: 額定中間消耗功率(W) | X1: 冷氣季節性能因數 CSPF | Z1: CSPF 實測/標示 | AA1: 標準 | AB1: 符合CSPF 節能標章 | AC1: 節能標章 證書編號 | AD1: 節能標章 有效日期 | AE1: 室外機型號 | AF1: 剩餘天數 | AG1: 能源效率分級 | AH1: 室外機型號 | AI1: 登錄編號
N2: 核對用 | P2: 實測值 | Q2: 標示值 | R2: 實測值 | S2: 標示值 | T2: 實測值 | U2: 標示值 | V2: 實測值 | W2: 標示值 | X2: 實測值 | Y2: 標示值 | AP2: 商品驗證登錄證書總數 | AQ2: =SUM(IF((G3:G131>=TODAY())*(F3:F131<>""), 1/COUNTIFS(F3:F131, F3:F131, G3:G131, ">="&TODAY()))) -> #VALUE!
A3: ETC | B3: RA | C3: RXV36ZVLT | D3: FTXV36ZVLT | F3: CI3A3161862273 | G3: 46738 | N3: 24-08-VAA-002 | O3: RXV36ZVLT | P3: 3.521 | Q3: 3.5 | R3: 1.686 | S3: 1.75 | T3: 772 | U3: 780 | V3: 274 | W3: 280 | X3: 6.48 | Y3: 6.53 | Z3: =X3/Y3 -> 0.99234303 | AC3: 11404278 | AD3: 46512 | AE3: RXV36ZVLT | AG3: 1 | AH3: RXV36ZVLT | AI3: ACN1-113-7799
A4: ETC | B4: RA | C4: RXV41ZVLT | D4: FTXV41ZVLT | F4: CI3A3161862301 | G4: 46747 | N4: 24-08-VAA-003 | O4: RXV41ZVLT | P4: 4.11 | Q4: 4.1 | R4: 1.833 | S4: 1.845 | T4: 994 | U4: 980 | V4: 307 | W4: 305 | X4: 6.17 | Y4: 6.24 | Z4: =X4/Y4 -> 0.98878205 | AC4: 11404278 | AD4: 46512 | AE4: RXV41ZVLT | AG4: 1 | AH4: RXV41ZVLT | AI4: ACN1-114-0104
A5: ETC | B5: RA | C5: RXV50ZVLT | D5: FTXV50ZVLT | F5: CI3A3161862301 | G5: 46747 | N5: 24-08-VAA-003 | O5: RXV50ZVLT | P5: 4.88 | Q5: 5 | R5: 2.332 | S5: 2.335 | T5: 1318 | U5: 1290 | V5: 401 | W5: 400 | X5: 5.88 | Y5: 5.96 | Z5: =X5/Y5 -> 0.98657718 | AC5: 11404278 | AD5: 46512 | AE5: RXV50ZVLT | AG5: 1 | AH5: RXV50ZVLT | AI5: ACN1-114-0103
A6: ETC | B6: RA | C6: RXV60ZVLT | D6: FTXV60ZVLT | F6: CI3A3161862301 | G6: 46747 | N6: 24-08-VAA-003 | O6: RXV60ZVLT | P6: 5.881 | Q6: 6 | R6: 2.734 | S6: 2.7 | T6: 1720 | U6: 1720 | V6: 510 | W6: 483 | X6: 5.35 | Y6: 5.61 | Z6: =X6/Y6 -> 0.95365419 | AG6: 1 | AH6: RXV60ZVLT | AI6: ACN1-114-0102
A7: ETC | B7: RA | C7: RXV71ZVLT | D7: FTXV71ZVLT | F7: CI3A3161862312 | G7: 46751 | N7: 24-08-VAA-004 | O7: RXV71ZVLT | P7: 7.146 | Q7: 7.2 | R7: 3.257 | S7: 3.24 | T7: 2059 | U7: 2150 | V7: 595 | W7: 603 | X7: 5.52 | Y7: 5.39 | Z7: =X7/Y7 -> 1.0241187 | AC7: 11404278 | AD7: 46512 | AE7: RXV71ZVLT | AG7: 1 | AH7: RXV71ZVLT | AI7: ACN1-114-0101
A8: TERTEC | B8: RA | C8: RHF20VAVLT | D8: FTHF20VAVLT | F8: CI3A5261862375 | G8: 47159 | N8: ACS20240899 | O8: RHF20VAVLT | P8: 2.18 | Q8: 2.2 | R8: 1.11 | S8: 1.1 | T8: 457 | U8: 465 | V8: 178 | W8: 185 | X8: 6.63 | Y8: 6.38 | Z8: =X8/Y8 -> 1.039185 | AC8: 1100313 | AD8: 46387 | AE8: RHF20VAVLT | AG8: 1 | AH8: RHF20VAVLT | AI8: ACN1-113-0224
A9: TERTEC | B9: RA | C9: RHF20ZVLT | D9: FTHF20ZVLT | F9: CI3A5261862375 | G9: 47159 | N9: ACS20240899 | O9: RHF20ZVLT | P9: 2.18 | Q9: 2.2 | R9: 1.11 | S9: 1.1 | T9: 457 | U9: 465 | V9: 178 | W9: 185 | X9: 6.63 | Y9: 6.38 | Z9: =X9/Y9 -> 1.039185 | AC9: 1140478 | AD9: 46527 | AE9: RHF20ZVLT | AG9: 1 | AH9: RHF20ZVLT | AI9: ACN1-113-2855 | AO9: RA | AP9: {=SUM(--(FREQUENCY(IF((B3:B195="RA")*(AC3:AC195<>""),MATCH(AC3:AC195,AC3:AC195,0)),ROW(AC3:AC195)-ROW(AC3)+1)>0))} -> 15
A10: TERTEC | B10: RA | C10: RHF25VAVLT | D10: FTHF25VAVLT | F10: CI3A5261862375 | G10: 47159 | N10: ACS20240899 | O10: RHF25VAVLT | P10: 2.49 | Q10: 2.5 | R10: 1.25 | S10: 1.25 | T10: 544 | U10: 550 | V10: 207 | W10: 210 | X10: 6.4 | Y10: 6.32 | Z10: =X10/Y10 -> 1.0126582 | AC10: 1100313 | AD10: 46387 | AE10: RHF25VAVLT | AG10: 1 | AH10: RHF25VAVLT | AI10: ACN1-113-0225 | AO10: MA | AP10: {=SUM(--(FREQUENCY(IF((B3:B195="MA")*(AC3:AC195<>""),MATCH(AC3:AC195,AC3:AC195,0)),ROW(AC3:AC195)-ROW(AC3)+1)>0))} -> 3
A11: TERTEC | B11: RA | C11: RHF25ZVLT | D11: FTHF25ZVLT | F11: CI3A5261862375 | G11: 47159 | N11: ACS20240899 | O11: RHF25ZVLT | P11: 2.49 | Q11: 2.5 | R11: 1.25 | S11: 1.25 | T11: 544 | U11: 550 | V11: 207 | W11: 210 | X11: 6.4 | Y11: 6.32 | Z11: =X11/Y11 -> 1.0126582 | AC11: 1140478 | AD11: 46527 | AE11: RHF25ZVLT | AG11: 1 | AH11: RHF25ZVLT | AI11: ACN1-113-2856 | AO11: SA | AP11: {=SUM(--(FREQUENCY(IF((B3:B195="SA")*(AC3:AC195<>""),MATCH(AC3:AC195,AC3:AC195,0)),ROW(AC3:AC195)-ROW(AC3)+1)>0))} -> 6
A12: TERTEC | B12: RA | C12: RHF30VAVLT | D12: FTHF30VAVLT | F12: CI3A5261862375 | G12: 47159 | N12: ACS20240899 | O12: RHF30VAVLT | P12: 2.97 | Q12: 3 | R12: 1.49 | S12: 1.5 | T12: 700 | U12: 684 | V12: 263 | W12: 253 | X12: 5.99 | Y12: 6.24 | Z12: =X12/Y12 -> 0.9599359 | AG12: 1 | AH12: RHF30VAVLT | AI12: ACN1-115-0721 | AO12: VRV | AP12: {=SUM(--(FREQUENCY(IF((B6:B198="VRV")*(AC6:AC198<>""),MATCH(AC6:AC198,AC6:AC198,0)),ROW(AC6:AC198)-ROW(AC6)+1)>0))} -> 13
A13: TERTEC | B13: RA | C13: RHF30ZVLT | D13: FTHF30ZVLT | F13: CI3A5261862375 | G13: 47159 | N13: ACS20240899 | O13: RHF30ZVLT | P13: 2.97 | Q13: 3 | R13: 1.49 | S13: 1.5 | T13: 700 | U13: 684 | V13: 263 | W13: 253 | X13: 5.99 | Y13: 6.24 | Z13: =X13/Y13 -> 0.9599359 | AG13: 1 | AH13: RHF30ZVLT | AI13: ACN1-113-2857
A14: TERTEC | B14: RA | C14: RHF40VAVLT | D14: FTHF40VAVLT | F14: CI3A5261862386 | G14: 47159 | N14: ACS20240899 | O14: RHF40VAVLT | P14: 4.04 | Q14: 4.1 | R14: 2.17 | S14: 2.08 | T14: 966 | U14: 1000 | V14: 369 | W14: 365 | X14: 6.15 | Y14: 5.96 | Z14: =X14/Y14 -> 1.0318792 | AC14: 1120418 | AD14: 45657 | AE14: RHF40VAVLT | AG14: 1 | AH14: RHF40VAVLT | AI14: ACN1-115-0729
A15: TERTEC | B15: RA | C15: RHF40VVLT | D15: FTHF40VVLT | F15: CI3A5261862386 | G15: 47159 | N15: ACS20240900 | O15: RHF40VVLT | P15: 4.04 | Q15: 4.1 | R15: 2.17 | S15: 2.08 | T15: 966 | U15: 1000 | V15: 369 | W15: 365 | X15: 6.15 | Y15: 5.96 | Z15: =X15/Y15 -> 1.0318792 | AG15: 1 | AH15: RHF40VVLT | AI15: ACN1-115-0732
A16: TERTEC | B16: RA | C16: RHF40ZVLT | D16: FTHF40ZVLT | F16: CI3A5261862386 | G16: 47159 | N16: ACS20240900 | O16: RHF40ZVLT | P16: 4.04 | Q16: 4.1 | R16: 2.17 | S16: 2.08 | T16: 966 | U16: 1000 | V16: 369 | W16: 365 | X16: 6.15 | Y16: 5.96 | Z16: =X16/Y16 -> 1.0318792 | AG16: 1 | AH16: RHF40ZVLT | AI16: ACN1-113-2858
A17: TERTEC | B17: RA | C17: RHF50VAVLT | D17: FTHF50VAVLT | F17: CI3A5261862386 | G17: 47159 | N17: ACS20240899 | O17: RHF50VAVLT | P17: 5.25 | Q17: 5 | R17: 2.42 | S17: 2.335 | T17: 1305 | U17: 1315 | V17: 407 | W17: 410 | X17: 6.1 | Y17: 5.83 | Z17: =X17/Y17 -> 1.0463122 | AC17: 1120419 | AD17: 46557 | AE17: RHF50VAVLT | AG17: 1 | AH17: RHF50VAVLT | AI17: ACN1-113-0034
A18: TERTEC | B18: RA | C18: RHF50VVLT | D18: FTHF50VVLT | F18: CI3A5261862386 | G18: 47159 | N18: ACS20240900 | O18: RHF50VVLT | P18: 5.25 | Q18: 5 | R18: 2.42 | S18: 2.335 | T18: 1305 | U18: 1315 | V18: 407 | W18: 410 | X18: 6.1 | Y18: 5.83 | Z18: =X18/Y18 -> 1.0463122 | AC18: 1100314 | AD18: 46387 | AE18: RHF50VVLT | AG18: 1 | AH18: RHF50VVLT | AI18: ACN1-113-0220
A19: TERTEC | B19: RA | C19: RHF50ZVLT | D19: FTHF50ZVLT | F19: CI3A5261862386 | G19: 47159 | N19: ACS20240900 | O19: RHF50ZVLT | P19: 5.25 | Q19: 5 | R19: 2.42 | S19: 2.335 | T19: 1305 | U19: 1315 | V19: 407 | W19: 410 | X19: 6.1 | Y19: 5.83 | Z19: =X19/Y19 -> 1.0463122 | AC19: 1140478 | AD19: 46527 | AE19: RHF50ZVLT | AG19: 1 | AH19: RHF50ZVLT | AI19: ACN1-113-2859
A20: TERTEC | B20: RA | C20: RHF60VVLT | D20: FTHF60VVLT | F20: CI3A5261862386 | G20: 47159 | N20: ACS20240900 | O20: RHF60VVLT | P20: 6.17 | Q20: 6 | R20: 2.99 | S20: 2.9 | T20: 1748 | U20: 1720 | V20: 555 | W20: 520 | X20: 5.49 | Y20: 5.61 | Z20: =X20/Y20 -> 0.97860963 | AG20: 1 | AH20: RHF60VVLT | AI20: ACN1-115-0733
A21: TERTEC | B21: RA | C21: RHF60VAVLT | D21: FTHF60VAVLT | F21: CI3A5261862386 | G21: 47159 | N21: ACS20240899 | O21: RHF60VAVLT | P21: 6.17 | Q21: 6 | R21: 2.99 | S21: 2.9 | T21: 1748 | U21: 1720 | V21: 555 | W21: 520 | X21: 5.49 | Y21: 5.61 | Z21: =X21/Y21 -> 0.97860963 | AC21: 1120418 | AD21: 45657 | AE21: RHF60VAVLT | AG21: 1 | AH21: RHF60VAVLT | AI21: ACN1-115-0730
A22: TERTEC | B22: RA | C22: RHF60ZVLT | D22: FTHF60ZVLT | F22: CI3A5261862386 | G22: 47159 | N22: ACS20240900 | O22: RHF60ZVLT | P22: 6.17 | Q22: 6 | R22: 2.99 | S22: 2.9 | T22: 1748 | U22: 1720 | V22: 555 | W22: 520 | X22: 5.49 | Y22: 5.61 | Z22: =X22/Y22 -> 0.97860963 | AG22: 1 | AH22: RHF60ZVLT | AI22: ACN1-113-2860
A23: TERTEC | B23: RA | C23: RHF71VVLT | D23: FTHF71VVLT | F23: CI3A5261862397 | G23: 47159 | N23: ACS20240901 | O23: RHF71VVLT | P23: 7.41 | Q23: 7.2 | R23: 3.76 | S23: 3.6 | T23: 2177 | U23: 2150 | V23: 710 | W23: 675 | X23: 5.38 | Y23: 5.38 | Z23: =X23/Y23 -> 1 | AG23: 1 | AH23: RHF71VVLT | AI23: ACN1-115-0734
A24: TERTEC | B24: RA | C24: RHF71VAVLT | D24: FTHF71VAVLT | F24: CI3A5261862397 | G24: 47159 | N24: ACS20240901 | O24: RHF71VAVLT | P24: 7.41 | Q24: 7.2 | R24: 3.76 | S24: 3.6 | T24: 2177 | U24: 2150 | V24: 710 | W24: 675 | X24: 5.38 | Y24: 5.38 | Z24: =X24/Y24 -> 1 | AC24: 1120418 | AD24: 45657 | AE24: RHF71VAVLT | AG24: 1 | AH24: RHF71VAVLT | AI24: ACN1-115-0731
A25: TERTEC | B25: RA | C25: RHF71ZVLT | D25: FTHF71ZVLT | F25: CI3A5261862397 | G25: 47159 | N25: ACS20240901 | O25: RHF71ZVLT | P25: 7.41 | Q25: 7.2 | R25: 3.76 | S25: 3.6 | T25: 2177 | U25: 2150 | V25: 710 | W25: 675 | X25: 5.38 | Y25: 5.38 | Z25: =X25/Y25 -> 1 | AG25: 1 | AH25: RHF71ZVLT | AI25: ACN1-113-2861
A26: TERTEC | B26: RA | C26: RKF71XVLT | D26: FAA71XVLT | F26: CI3A5261862397 | G26: 47159 | N26: ACS20240901 | O26: RKF71XVLT | P26: 7.41 | Q26: 7.2 | R26: 3.76 | S26: 3.6 | T26: 2177 | U26: 2150 | V26: 710 | W26: 675 | X26: 5.38 | Y26: 5.38 | Z26: =X26/Y26 -> 1 | AC26: 1120418 | AD26: 45657 | AE26: RKF71XVLT | AG26: 2 | AH26: RKF71XVLT | AI26: ACN1-113-0223
A27: ETC | B27: RA | C27: RXM22ZVLT | D27: FTXM22ZVLT | F27: CI3A3161862171 | G27: 46670 | N27: 24-06-VAA-038 | O27: RXM22ZVLT | P27: 2.197 | Q27: 2.2 | R27: 1.032 | S27: 1.02 | T27: 415 | U27: 435 | V27: 160 | W27: 158 | X27: 6.99 | Y27: 6.9 | Z27: =X27/Y27 -> 1.0130435 | AC27: 1140323 | AD27: 46493 | AE27: RXM22ZVLT | AG27: 1 | AH27: RXM22ZVLT | AI27: ACN1-113-4128
A28: ETC | B28: RA | C28: RXM28ZVLT | D28: FTXM28ZVLT | F28: CI3A3161862171 | G28: 46670 | N28: 24-06-VAA-038 | O28: RXM28ZVLT | P28: 2.885 | Q28: 2.8 | R28: 1.267 | S28: 1.29 | T28: 594 | U28: 600 | V28: 202 | W28: 206 | X28: 6.69 | Y28: 6.6 | Z28: =X28/Y28 -> 1.0136364 | AC28: 1140323 | AD28: 46493 | AE28: RXM28ZVLT | AG28: 1 | AH28: RXM28ZVLT | AI28: ACN1-113-4127
A29: ETC | B29: RA | C29: RXM36ZVLT | D29: FTXM36ZVLT | F29: CI3A3161862182 | G29: 46675 | N29: 24-06-VAA-039 | O29: RXM36ZVLT | P29: 3.568 | Q29: 3.5 | R29: 1.706 | S29: 1.71 | T29: 764 | U29: 780 | V29: 260 | W29: 257 | X29: 6.83 | Y29: 6.84 | Z29: =X29/Y29 -> 0.99853801 | AC29: 1140323 | AD29: 46493 | AE29: RXM36ZVLT | AG29: 1 | AH29: RXM36ZVLT | AI29: ACN1-113-4278
A30: ETC | B30: RA | C30: RXM41ZVLT | D30: FTXM41ZVLT | F30: CI3A3161862193 | G30: 46687 | N30: 24-06-VAA-040 | O30: RXM41ZVLT | P30: 4.192 | Q30: 4.1 | R30: 1.947 | S30: 1.94 | T30: 994 | U30: 995 | V30: 307 | W30: 301 | X30: 6.48 | Y30: 6.52 | Z30: =X30/Y30 -> 0.99386503 | AC30: 1140323 | AD30: 46493 | AE30: RXM41ZVLT | AG30: 1 | AH30: RXM41ZVLT | AI30: ACN1-113-4279
A31: ETC | B31: RA | C31: RXM50ZVLT | D31: FTXM50ZVLT | F31: CI3A3161862193 | G31: 46687 | N31: 24-06-VAA-040 | O31: RXM50ZVLT | P31: 5.092 | Q31: 5 | R31: 2.361 | S31: 2.41 | T31: 1368 | U31: 1370 | V31: 394 | W31: 404 | X31: 6.01 | Y31: 5.97 | Z31: =X31/Y31 -> 1.0067002 | AC31: 1140323 | AD31: 46493 | AE31: RXM50ZVLT | AG31: 1 | AH31: RXM50ZVLT | AI31: ACN1-113-4280
A32: ETC | B32: RA | C32: RXM60ZVLT | D32: FTXM60ZVLT | F32: CI3A3161862221 | G32: 46696 | N32: 24-07-VAA-001 | O32: RXM60ZVLT | P32: 6.197 | Q32: 6 | R32: 2.924 | S32: 2.82 | T32: 1529 | U32: 1580 | V32: 454 | W32: 466 | X32: 6.36 | Y32: 6.2 | Z32: =X32/Y32 -> 1.0258065 | AC32: 1140322 | AD32: 46493 | AE32: RXM60ZVLT | AG32: 1 | AH32: RXM60ZVLT | AI32: ACN1-113-5397
A33: ETC | B33: RA | C33: RXM71ZVLT | D33: FTXM71ZVLT | F33: CI3A3161862232 | G33: 46698 | N33: 24-07-VAA-002 | O33: RXM71ZVLT | P33: 7.384 | Q33: 7.2 | R33: 3.467 | S33: 3.5 | T33: 2087 | U33: 2090 | V33: 605 | W33: 590 | X33: 5.75 | Y33: 5.86 | Z33: =X33/Y33 -> 0.98122867 | AC33: 1140322 | AD33: 46493 | AE33: RXM71ZVLT | AG33: 1 | AH33: RXM71ZVLT | AI33: ACN1-113-5407
A34: ETC | B34: RA | C34: RXM80ZVLT | D34: FTXM80ZVLT | F34: CI3A3161862240 | G34: 46698 | N34: 24-07-VAA-003 | O34: RXM80ZVLT | P34: 8.243 | Q34: 8 | R34: 3.652 | S34: 3.68 | T34: 2134 | U34: 2120 | V34: 630 | W34: 621 | X34: 5.92 | Y34: 5.98 | Z34: =X34/Y34 -> 0.98996656 | AC34: 1140322 | AD34: 46493 | AE34: RXM80ZVLT | AG34: 1 | AH34: RXM80ZVLT | AI34: ACN1-113-5408
A35: ETC | B35: RA | C35: RXM90ZVLT | D35: FTXM90ZVLT | F35: CI3A3161862240 | G35: 46698 | N35: 24-07-VAA-003 | O35: RXM90ZVLT | P35: 9.076 | Q35: 8.7 | R35: 4.052 | S35: 4.01 | T35: 2384 | U35: 2400 | V35: 724 | W35: 702 | X35: 5.75 | Y35: 5.76 | Z35: =X35/Y35 -> 0.99826389 | AC35: 1140322 | AD35: 46493 | AE35: RXM90ZVLT | AG35: 1 | AH35: RXM90ZVLT | AI35: ACN1-113-5409
A36: MIRDC | B36: RA | C36: RXM22YVLT | D36: FTXM22YVLT | F36: CI3A2561862024 | G36: 46388 | N36: 2306001-S | O36: RXM22YVLT | P36: 2.391 | Q36: 2.2 | R36: 1.099 | S36: 1.047 | T36: 371 | U36: 360 | V36: 145.9 | W36: 147 | X36: 8.26 | Y36: 7.81 | Z36: =X36/Y36 -> 1.0576184 | AC36: 11303718 | AD36: 46163 | AE36: RXM22YVLT | AG36: 1 | AH36: RXM22YVLT | AI36: ACN1-113-0293
A37: MIRDC | B37: RA | C37: RXM28YVLT | D37: FTXM28YVLT | F37: CI3A2561862024 | G37: 46388 | N37: 2306001-S | O37: RXM28YVLT | P37: 2.9979 | Q37: 2.8 | R37: 1.4023 | S37: 1.336 | T37: 512.3 | U37: 496 | V37: 188.1 | W37: 192 | X37: 7.97 | Y37: 7.51 | Z37: =X37/Y37 -> 1.0612517 | AC37: 11303718 | AD37: 46163 | AE37: RXM28YVLT | AG37: 1 | AH37: RXM28YVLT | AI37: ACN1-113-0294
A38: MIRDC | B38: RA | C38: RXM36YVLT | D38: FTXM36YVLT | F38: CI3A2561862024 | G38: 46388 | N38: 2306001-S | O38: RXM36YVLT | P38: 3.7719 | Q38: 3.5 | R38: 1.7536 | S38: 1.671 | T38: 760.6 | U38: 734 | V38: 237.3 | W38: 244 | X38: 7.57 | Y38: 7.09 | Z38: =X38/Y38 -> 1.067701 | AC38: 11303718 | AD38: 46163 | AE38: RXM36YVLT | AG38: 1 | AH38: RXM36YVLT | AI38: ACN1-113-0295
... A42: MIRDC | B42: RA | C42: RXM71YVLT | D42: FTXM71YVLT | F42: CI3A2561861990 | G42: 46388 | N42: 2306004-S | O42: RXM71YVLT | P42: 7.3933 | Q42: 7.2 | R42: 3.5503 | S42: 3.382 | T42: 1892.4 | U42: 1890 | V42: 514 | W42: 540 | X42: 6.77 | Y42: 6.25 | Z42: =X42/Y42 -> 1.0832 | AC42: 1130372 | AD42: 46163 | AE42: RXM71YVLT | AG42: 1 | AH42: RXM71YVLT | AI42: ACN1-113-0299
A43: TERTEC | B43: MA | C43: 3MXM90PVLT | F43: CI3A2261861837 | G43: 46187 | N43: ACT20230204 | O43: 3MXM90PVLT | P43: 8.57 | Q43: 8.5 | R43: 4.28 | S43: 4.28 | T43: 2247 | U43: 2330 | V43: 765 | W43: 765 | X43: 5.71 | Y43: 5.77 | Z43: =X43/Y43 -> 0.98960139 | AG43: 1 | AH43: 3MXM90PVLT | AI43: ACN1-113-0043
...

Sheet 工作表2
A1: 實驗室 | B1: 類別 | C1: 室外機型號 | D1: 測試搭配 (無風管內機型號) | E1: 核備 | F1: 商品驗證登錄證書編號 | G1: 證書有效 期限 | H1: 2027年 年費 | I1: 已展延 | J1: 分類 | K1: 計算用 | L1: 計算用 | M1: 計算用 | N1: 安規測試 報告編號 | O1: 室外機型號 | P1: 額定冷氣能力 | R1: 中間冷氣能力 | T1: 額定消耗功率 | V1: 額定中間消耗功率 | X1: 冷氣季節性能因數 CSPF | Z1: 效率等級 | AA1: 標準 | AB1: 符合CSPF 節能標章 | AC1: 節能標章 證書編號 | AD1: 節能標章 有效日期 | AE1: 分類 | AF1: 剩餘天數 | AG1: 能源效率分級 | AH1: 商品驗證登錄證書URL | AI1: 節能標章 證書編號 URL | AJ1: 安規報告書URL | AK1: 能源效率分級URL
N2: 核對用 | P2: 實測值 | Q2: 標示值 | R2: 實測值 | S2: 標示值 | T2: 實測值 | U2: 標示值 | V2: 實測值 | W2: 標示值 | X2: 實測值 | Y2: 標示值
AL51: 未配對室內機：FTXM22YVLT、FTXM28YVLT、FTXM36YVLT、FTXM41YVLT、FTXMS0YVLT、FTXM6GOYVLT
AL52: 未配對室內機：FBA71BVLT
AL53: 未配對室內機：FXAQ20AVLT、FXAQ25AVLT、FXAQ32AVLT、FXAQ40AVLT、FXAQ50AVLT、FXCQ20BVT、FXCQ25BVT、FXCQ32BVT、FXCQ40BVT、FXCQ50BVT、FXDQ20PDNVT、FXDQ20PDVT、FXDQ25PDNVT、FXDQ25PDVT、FXDQ32PDNVT、FXDQ32PDVT、FXDQ40NDNVT、FXDQ40NDVT、FXDQ50NDNVT、FXDQ50NDVT、FXFQ25BVT、FXFQ32BVT、FXFQ40BVT、FXFQ50BVT、FXFSQ25BVT、FXFSQ32BVT、FXFSQ40BVT、FXFSQ50BVT、FXMQ20PAVT、FXMQ25PAVT、FXMQ32PAVT、FXMQ40PAVT、FXMQ50PAVT、FXSQ20PAVT、FXSQ25PAVT、FXSQ32PAVT、FXSQ40PAVT、FXSQ50PAVT、FXZQ20BVLT、FXZQ25BVLT、FXZQ32BVLT、FXZQ40BVLT、FXZQ50BVLT
AL54: 未配對室內機：FXCQ20MVET、FXCQ25、FXCQ40、FXCQ63MVET、FXCQ80MVET、FXCQ125MVET、FXFQ25、FXZQ20

Sheet 到期清單
A1: 商品驗證登錄證書 — 即將到期（90天內） | F1: 節能標章 — 即將到期（90天內）
A2: 證書編號 | B2: 有效日期 | C2: 剩餘天數 | D2: 類別 | F2: 證書編號 | G2: 有效日期 | H2: 剩餘天數 | I2: 類別
A3: CI3A2261861837 | B3: 46187 | C3: 23 | D3: MA | F3: 1110286 | G3: 46165 | H3: 1 | I3: VRV
A4: CI3A2261861848 | B4: 46192 | C4: 28 | D4: MA
A5: CI3A2261861890 | B5: 46227 | C5: 63 | D5: SA
A6: CI3A9261861510 | B6: 46195 | C6: 31 | D6: SA
A7: CI3A2261861917 | B7: 46235 | C7: 71 | D7: VRV
A8: CI3A2261861928 | B8: 46241 | C8: 77 | D8: VRV

Sheet 圖表資料
A1: 圖表資料（自動計算）
A3: 商品驗證 各類別 | D3: 節能標章 各類別
A4: 類別 | B4: 有效張數（去重） | D4: 類別 | E4: 有效張數（去重）
A5: RA | B5: =SUMPRODUCT((工作表1!B$3:B$131="RA")*(工作表1!G$3:G$131>=TODAY())*(工作表1!F$3:F$131<>"")/IF(COUNTIFS(工作表1!B$3:B$131,"RA",工作表1!F$3:F$131,工作表1!F$3:F$131)=0,1,COUNTIFS(工作表1!B$3:B$131,"RA",工作表1!F$3:F$131,工作表1!F$3:F$131))) -> 14 | D5: RA | E5: {=SUM(--(FREQUENCY(IF((工作表1!B$3:B$195="RA")*(工作表1!AD$3:AD$195>=TODAY())*(工作表1!AC$3:AC$195<>""),MATCH(工作表1!AC$3:AC$195,工作表1!AC$3:AC$195,0)),ROW(工作表1!AC$3:AC$195)-ROW(工作表1!AC$3)+1)>0))} -> 12
A6: MA | B6: =SUMPRODUCT((工作表1!B$3:B$131="MA")*(工作表1!G$3:G$131>=TODAY())*(工作表1!F$3:F$131<>"")/IF(COUNTIFS(工作表1!B$3:B$131,"MA",工作表1!F$3:F$131,工作表1!F$3:F$131)=0,1,COUNTIFS(工作表1!B$3:B$131,"MA",工作表1!F$3:F$131,工作表1!F$3:F$131))) -> 11 | D6: MA | E6: {=SUMPRODUCT((工作表1!B$3:B$195="MA")*(工作表1!AD$3:AD$195>=TODAY())*(工作表1!AC$3:AC$195<>"")/IF(COUNTIFS(工作表1!B$3:B$195,"MA",工作表1!AC$3:AC$195,工作表1!AC$3:AC$195)=0,1,COUNTIFS(工作表1!B$3:B$195,"MA",工作表1!AC$3:AC$195,工作表1!AC$3:AC$195)))} -> 3
A7: SA | B7: =SUMPRODUCT((工作表1!B$3:B$131="SA")*(工作表1!G$3:G$131>=TODAY())*(工作表1!F$3:F$131<>"")/IF(COUNTIFS(工作表1!B$3:B$131,"SA",工作表1!F$3:F$131,工作表1!F$3:F$131)=0,1,COUNTIFS(工作表1!B$3:B$131,"SA",工作表1!F$3:F$131,工作表1!F$3:F$131))) -> 24 | D7: SA | E7: {=SUMPRODUCT((工作表1!B$3:B$195="SA")*(工作表1!AD$3:AD$195>=TODAY())*(工作表1!AC$3:AC$195<>"")/IF(COUNTIFS(工作表1!B$3:B$195,"SA",工作表1!AC$3:AC$195,工作表1!AC$3:AC$195)=0,1,COUNTIFS(工作表1!B$3:B$195,"SA",工作表1!AC$3:AC$195,工作表1!AC$3:AC$195)))} -> 6
A8: VRV | B8: =SUMPRODUCT((工作表1!B$3:B$131="VRV")*(工作表1!G$3:G$131>=TODAY())*(工作表1!F$3:F$131<>"")/IF(COUNTIFS(工作表1!B$3:B$131,"VRV",工作表1!F$3:F$131,工作表1!F$3:F$131)=0,1,COUNTIFS(工作表1!B$3:B$131,"VRV",工作表1!F$3:F$131,工作表1!F$3:F$131))) -> 45 | D8: VRV | E8: {=SUMPRODUCT((工作表1!B$3:B$195="VRV")*(工作表1!AD$3:AD$195>=TODAY())*(工作表1!AC$3:AC$195<>"")/IF(COUNTIFS(工作表1!B$3:B$195,"VRV",工作表1!AC$3:AC$195,工作表1!AC$3:AC$195)=0,1,COUNTIFS(工作表1!B$3:B$195,"VRV",工作表1!AC$3:AC$195,工作表1!AC$3:AC$195)))} -> 11
A9: 合計 | B9: =SUMPRODUCT((工作表1!G$3:G$131>=TODAY())*(工作表1!F$3:F$131<>"")/COUNTIF(工作表1!F$3:F$131,工作表1!F$3:F$131&"")) -> 66 | D9: 合計 | E9: =SUMPRODUCT((工作表1!AD$3:AD$195>=TODAY())*(工作表1!AC$3:AC$195<>"")/COUNTIF(工作表1!AC$3:AC$195,工作表1!AC$3:AC$195&"")) -> 31
A11: 每半年到期件數（合併）
A12: 期間 | B12: 商品驗證 | D12: 節能標章
A13: =IF(MONTH(EDATE(DATE(YEAR(TODAY()),IF(MONTH(TODAY())<=6,1,7),1),0))<=6,TEXT(YEAR(EDATE(DATE(YEAR(TODAY()),IF(MONTH(TODAY())<=6,1,7),1),0)),"0000")&"上半",TEXT(YEAR(EDATE(DATE(YEAR(TODAY()),IF(MONTH(TODAY())<=6,1,7),1),0)),"0000")&"下半") -> 2026上半 | B13: =COUNTIFS(工作表1!G$3:G$131,">="&EDATE(DATE(YEAR(TODAY()),IF(MONTH(TODAY())<=6,1,7),1),0),工作表1!G$3:G$131,"<="&(EDATE(DATE(YEAR(TODAY()),IF(MONTH(TODAY())<=6,1,7),1),6)-1)) -> 14 | D13: =COUNTIFS(工作表1!AD$3:AD$131,">="&EDATE(DATE(YEAR(TODAY()),IF(MONTH(TODAY())<=6,1,7),1),0),工作表1!AD$3:AD$131,"<="&(EDATE(DATE(YEAR(TODAY()),IF(MONTH(TODAY())<=6,1,7),1),6)-1)) -> 11
A14: =IF(MONTH(EDATE(DATE(YEAR(TODAY()),IF(MONTH(TODAY())<=6,1,7),1),6))<=6,TEXT(YEAR(EDATE(DATE(YEAR(TODAY()),IF(MONTH(TODAY())<=6,1,7),1),6)),"0000")&"上半",TEXT(YEAR(EDATE(DATE(YEAR(TODAY()),IF(MONTH(TODAY())<=6,1,7),1),6)),"0000")&"下半") -> 2026下半 | B14: =COUNTIFS(工作表1!G$3:G$131,">="&EDATE(DATE(YEAR(TODAY()),IF(MONTH(TODAY())<=6,1,7),1),6),工作表1!G$3:G$131,"<="&(EDATE(DATE(YEAR(TODAY()),IF(MONTH(TODAY())<=6,1,7),1),12)-1)) -> 12 | D14: =COUNTIFS(工作表1!AD$3:AD$131,">="&EDATE(DATE(YEAR(TODAY()),IF(MONTH(TODAY())<=6,1,7),1),6),工作表1!AD$3:AD$131,"<="&(EDATE(DATE(YEAR(TODAY()),IF(MONTH(TODAY())<=6,1,7),1),12)-1)) -> 28
A15: =IF(MONTH(EDATE(DATE(YEAR(TODAY()),IF(MONTH(TODAY())<=6,1,7),1),12))<=6,TEXT(YEAR(EDATE(DATE(YEAR(TODAY()),IF(MONTH(TODAY())<=6,1,7),1),12)),"0000")&"上半",TEXT(YEAR(EDATE(DATE(YEAR(TODAY()),IF(MONTH(TODAY())<=6,1,7),1),12)),"0000")&"下半") -> 2027上半 | B15: =COUNTIFS(工作表1!G$3:G$131,">="&EDATE(DATE(YEAR(TODAY()),IF(MONTH(TODAY())<=6,1,7),1),12),工作表1!G$3:G$131,"<="&(EDATE(DATE(YEAR(TODAY()),IF(MONTH(TODAY())<=6,1,7),1),18)-1)) -> 27 | D15: =COUNTIFS(工作表1!AD$3:AD$131,">="&EDATE(DATE(YEAR(TODAY()),IF(MONTH(TODAY())<=6,1,7),1),12),工作表1!AD$3:AD$131,"<="&(EDATE(DATE(YEAR(TODAY()),IF(MONTH(TODAY())<=6,1,7),1),18)-1)) -> 26
A16: =IF(MONTH(EDATE(DATE(YEAR(TODAY()),IF(MONTH(TODAY())<=6,1,7),1),18))<=6,TEXT(YEAR(EDATE(DATE(YEAR(TODAY()),IF(MONTH(TODAY())<=6,1,7),1),18)),"0000")&"上半",TEXT(YEAR(EDATE(DATE(YEAR(TODAY()),IF(MONTH(TODAY())<=6,1,7),1),18)),"0000")&"下半") -> 2027下半 | B16: =COUNTIFS(工作表1!G$3:G$131,">="&EDATE(DATE(YEAR(TODAY()),IF(MONTH(TODAY())<=6,1,7),1),18),工作表1!G$3:G$131,"<="&(EDATE(DATE(YEAR(TODAY()),IF(MONTH(TODAY())<=6,1,7),1),24)-1)) -> 16 | D16: =COUNTIFS(工作表1!AD$3:AD$131,">="&EDATE(DATE(YEAR(TODAY()),IF(MONTH(TODAY())<=6,1,7),1),18),工作表1!AD$3:AD$131,"<="&(EDATE(DATE(YEAR(TODAY()),IF(MONTH(TODAY())<=6,1,7),1),24)-1)) -> 18
A17: =IF(MONTH(EDATE(DATE(YEAR(TODAY()),IF(MONTH(TODAY())<=6,1,7),1),24))<=6,TEXT(YEAR(EDATE(DATE(YEAR(TODAY()),IF(MONTH(TODAY())<=6,1,7),1),24)),"0000")&"上半",TEXT(YEAR(EDATE(DATE(YEAR(TODAY()),IF(MONTH(TODAY())<=6,1,7),1),24)),"0000")&"下半") -> 2028上半 | B17: =COUNTIFS(工作表1!G$3:G$131,">="&EDATE(DATE(YEAR(TODAY()),IF(MONTH(TODAY())<=6,1,7),1),24),工作表1!G$3:G$131,"<="&(EDATE(DATE(YEAR(TODAY()),IF(MONTH(TODAY())<=6,1,7),1),30)-1)) -> 7 | D17: =COUNTIFS(工作表1!AD$3:AD$131,">="&EDATE(DATE(YEAR(TODAY()),IF(MONTH(TODAY())<=6,1,7),1),24),工作表1!AD$3:AD$131,"<="&(EDATE(DATE(YEAR(TODAY()),IF(MONTH(TODAY())<=6,1,7),1),30)-1)) -> 0
A18: =IF(MONTH(EDATE(DATE(YEAR(TODAY()),IF(MONTH(TODAY())<=6,1,7),1),30))<=6,TEXT(YEAR(EDATE(DATE(YEAR(TODAY()),IF(MONTH(TODAY())<=6,1,7),1),30)),"0000")&"上半",TEXT(YEAR(EDATE(DATE(YEAR(TODAY()),IF(MONTH(TODAY())<=6,1,7),1),30)),"0000")&"下半") -> 2028下半 | B18: =COUNTIFS(工作表1!G$3:G$131,">="&EDATE(DATE(YEAR(TODAY()),IF(MONTH(TODAY())<=6,1,7),1),30),工作表1!G$3:G$131,"<="&(EDATE(DATE(YEAR(TODAY()),IF(MONTH(TODAY())<=6,1,7),1),36)-1)) -> 6 | D18: =COUNTIFS(工作表1!AD$3:AD$131,">="&EDATE(DATE(YEAR(TODAY()),IF(MONTH(TODAY())<=6,1,7),1),30),工作表1!AD$3:AD$131,"<="&(EDATE(DATE(YEAR(TODAY()),IF(MONTH(TODAY())<=6,1,7),1),36)-1)) -> 0
G20: 能效分級統計（AG欄）
G21: 類別 | H21: 1級 | I21: 2級 | J21: 3級 | K21: 合計
G22: RA | H22: =COUNTIFS(工作表1!B$3:B$131,"RA",工作表1!AG$3:AG$131,1) -> 41 | I22: =COUNTIFS(工作表1!B$3:B$131,"RA",工作表1!AG$3:AG$131,2) -> 1 | J22: =COUNTIFS(工作表1!B$3:B$131,"RA",工作表1!AG$3:AG$131,3) -> 0 | K22: =COUNTIF(工作表1!B$3:B$131,"RA") -> 42
G23: MA | H23: =COUNTIFS(工作表1!B$3:B$131,"MA",工作表1!AG$3:AG$131,1) -> 15 | I23: =COUNTIFS(工作表1!B$3:B$131,"MA",工作表1!AG$3:AG$131,2) -> 1 | J23: =COUNTIFS(工作表1!B$3:B$131,"MA",工作表1!AG$3:AG$131,3) -> 0 | K23: =COUNTIF(工作表1!B$3:B$131,"MA") -> 16
G24: SA | H24: =COUNTIFS(工作表1!B$3:B$131,"SA",工作表1!AG$3:AG$131,1) -> 19 | I24: =COUNTIFS(工作表1!B$3:B$131,"SA",工作表1!AG$3:AG$131,2) -> 7 | J24: =COUNTIFS(工作表1!B$3:B$131,"SA",工作表1!AG$3:AG$131,3) -> 0 | K24: =COUNTIF(工作表1!B$3:B$131,"SA") -> 26
G25: VRV | H25: =COUNTIFS(工作表1!B$3:B$131,"VRV",工作表1!AG$3:AG$131,1) -> 38 | I25: =COUNTIFS(工作表1!B$3:B$131,"VRV",工作表1!AG$3:AG$131,2) -> 5 | J25: =COUNTIFS(工作表1!B$3:B$131,"VRV",工作表1!AG$3:AG$131,3) -> 2 | K25: =COUNTIF(工作表1!B$3:B$131,"VRV") -> 45
G27: 節能標章取得百分比（AE/C）
G28: 類別 | H28: 有效型號(C) | I28: 取得標章(AE) | J28: 取得率
G29: RA | H29: {=SUM(--(FREQUENCY(IF((工作表1!B$3:B$131="RA")*(LOOKUP(ROW(工作表1!G$3:G$131),ROW(工作表1!G$3:G$131)/(工作表1!G$3:G$131<>""),工作表1!G$3:G$131)>=TODAY())*(工作表1!C$3:C$131<>""),MATCH(工作表1!C$3:C$131,工作表1!C$3:C$131,0)),ROW(工作表1!C$3:C$131)-ROW(工作表1!C$3)+1)>0))} -> 42 | I29: {=SUM(--(FREQUENCY(IF((工作表1!B$3:B$131="RA")*(工作表1!C$3:C$131<>"")*(工作表1!AC$3:AC$131<>"")*(LOOKUP(ROW(工作表1!G$3:G$131),ROW(工作表1!G$3:G$131)/(工作表1!G$3:G$131<>""),工作表1!G$3:G$131)>=TODAY()),MATCH(工作表1!C$3:C$131,工作表1!C$3:C$131,0)),ROW(工作表1!C$3:C$131)-ROW(工作表1!C$3)+1)>0))} -> 33 | J29: =IFERROR(圖表資料!I29/圖表資料!H29,0) -> 0.78571429 | L29: RA | M29: =J29 -> 0.78571429 | N29: =1-M29 -> 0.21428571
G30: MA | H30: {=SUM(--(FREQUENCY(IF((工作表1!B$3:B$131="MA")*(LOOKUP(ROW(工作表1!G$3:G$131),ROW(工作表1!G$3:G$131)/(工作表1!G$3:G$131<>""),工作表1!G$3:G$131)>=TODAY())*(工作表1!C$3:C$131<>""),MATCH(工作表1!C$3:C$131,工作表1!C$3:C$131,0)),ROW(工作表1!C$3:C$131)-ROW(工作表1!C$3)+1)>0))} -> 11 | I30: {=SUM(--(FREQUENCY(IF((工作表1!B$3:B$131="MA")*(工作表1!C$3:C$131<>"")*(工作表1!AC$3:AC$131<>"")*(LOOKUP(ROW(工作表1!G$3:G$131),ROW(工作表1!G$3:G$131)/(工作表1!G$3:G$131<>""),工作表1!G$3:G$131)>=TODAY()),MATCH(工作表1!C$3:C$131,工作表1!C$3:C$131,0)),ROW(工作表1!C$3:C$131)-ROW(工作表1!C$3)+1)>0))} -> 7 | J30: =IFERROR(圖表資料!I30/圖表資料!H30,0) -> 0.63636364 | L30: MA | M30: =J30 -> 0.63636364 | N30: =1-M30 -> 0.36363636
G31: SA | H31: {=SUM(--(FREQUENCY(IF((工作表1!B$3:B$131="SA")*(LOOKUP(ROW(工作表1!G$3:G$131),ROW(工作表1!G$3:G$131)/(工作表1!G$3:G$131<>""),工作表1!G$3:G$131)>=TODAY())*(工作表1!C$3:C$131<>""),MATCH(工作表1!C$3:C$131,工作表1!C$3:C$131,0)),ROW(工作表1!C$3:C$131)-ROW(工作表1!C$3)+1)>0))} -> 24 | I31: {=SUM(--(FREQUENCY(IF((工作表1!B$3:B$131="SA")*(工作表1!C$3:C$131<>"")*(工作表1!AC$3:AC$131<>"")*(LOOKUP(ROW(工作表1!G$3:G$131),ROW(工作表1!G$3:G$131)/(工作表1!G$3:G$131<>""),工作表1!G$3:G$131)>=TODAY()),MATCH(工作表1!C$3:C$131,工作表1!C$3:C$131,0)),ROW(工作表1!C$3:C$131)-ROW(工作表1!C$3)+1)>0))} -> 17 | J31: =IFERROR(圖表資料!I31/圖表資料!H31,0) -> 0.70833333 | L31: SA | M31: =J31 -> 0.70833333 | N31: =1-M31 -> 0.29166667
G32: VRV | H32: {=SUM(--(FREQUENCY(IF((工作表1!B$3:B$131="VRV")*(LOOKUP(ROW(工作表1!G$3:G$131),ROW(工作表1!G$3:G$131)/(工作表1!G$3:G$131<>""),工作表1!G$3:G$131)>=TODAY())*(工作表1!C$3:C$131<>""),MATCH(工作表1!C$3:C$131,工作表1!C$3:C$131,0)),ROW(工作表1!C$3:C$131)-ROW(工作表1!C$3)+1)>0))} -> 45 | I32: {=SUM(--(FREQUENCY(IF((工作表1!B$3:B$131="VRV")*(工作表1!C$3:C$131<>"")*(工作表1!AC$3:AC$131<>"")*(LOOKUP(ROW(工作表1!G$3:G$131),ROW(工作表1!G$3:G$131)/(工作表1!G$3:G$131<>""),工作表1!G$3:G$131)>=TODAY()),MATCH(工作表1!C$3:C$131,工作表1!C$3:C$131,0)),ROW(工作表1!C$3:C$131)-ROW(工作表1!C$3)+1)>0))} -> 28 | J32: =IFERROR(圖表資料!I32/圖表資料!H32,0) -> 0.62222222 | L32: VRV | M32: =J32 -> 0.62222222 | N32: =1-M32 -> 0.37777778
H33: =SUM(H29:H32) -> 122 | I33: =SUM(I29:I32) -> 85 | J33: =I33/H33 -> 0.69672131
G34: CSPF 分布（Z欄 X/Y）
G35: 比值 | H35: RA | I35: MA | J35: SA | K35: VRV
G36: 95% | H36: =SUMPRODUCT((工作表1!B$3:B$195="RA")*(工作表1!Z$3:Z$195>=95%)*(工作表1!Z$3:Z$195<96%)*(LOOKUP(ROW(工作表1!G$3:G$195),ROW(工作表1!G$3:G$195)/(工作表1!G$3:G$195<>""),工作表1!G$3:G$195)>=TODAY())) -> 3 | I36: =SUMPRODUCT((工作表1!B$3:B$195="MA")*(工作表1!Z$3:Z$195>=95%)*(工作表1!Z$3:Z$195<96%)*(LOOKUP(ROW(工作表1!G$3:G$195),ROW(工作表1!G$3:G$195)/(工作表1!G$3:G$195<>""),工作表1!G$3:G$195)>=TODAY())) -> 0 | J36: =SUMPRODUCT((工作表1!B$3:B$195="SA")*(工作表1!Z$3:Z$195>=95%)*(工作表1!Z$3:Z$195<96%)*(LOOKUP(ROW(工作表1!G$3:G$195),ROW(工作表1!G$3:G$195)/(工作表1!G$3:G$195<>""),工作表1!G$3:G$195)>=TODAY())) -> 0 | K36: =SUMPRODUCT((工作表1!B$3:B$195="VRV")*(工作表1!Z$3:Z$195>=95%)*(工作表1!Z$3:Z$195<96%)*(LOOKUP(ROW(工作表1!G$3:G$195),ROW(工作表1!G$3:G$195)/(工作表1!G$3:G$195<>""),工作表1!G$3:G$195)>=TODAY())) -> 27
G37: 96% | H37: =SUMPRODUCT((工作表1!B$3:B$195="RA")*(工作表1!Z$3:Z$195>=96%)*(工作表1!Z$3:Z$195<97%)*(LOOKUP(ROW(工作表1!G$3:G$195),ROW(工作表1!G$3:G$195)/(工作表1!G$3:G$195<>""),工作表1!G$3:G$195)>=TODAY())) -> 0 | I37: =SUMPRODUCT((工作表1!B$3:B$195="MA")*(工作表1!Z$3:Z$195>=96%)*(工作表1!Z$3:Z$195<97%)*(LOOKUP(ROW(工作表1!G$3:G$195),ROW(工作表1!G$3:G$195)/(工作表1!G$3:G$195<>""),工作表1!G$3:G$195)>=TODAY())) -> 0 | J37: =SUMPRODUCT((工作表1!B$3:B$195="SA")*(工作表1!Z$3:Z$195>=96%)*(工作表1!Z$3:Z$195<97%)*(LOOKUP(ROW(工作表1!G$3:G$195),ROW(工作表1!G$3:G$195)/(工作表1!G$3:G$195<>""),工作表1!G$3:G$195)>=TODAY())) -> 2 | K37: =COUNTIFS(工作表1!B$3:B$131,"VRV",工作表1!Z$3:Z$131,">="&0.96,工作表1!Z$3:Z$131,"<"&0.97) -> 5
G38: 97% | H38: =SUMPRODUCT((工作表1!B$3:B$195="RA")*(工作表1!Z$3:Z$195>=97%)*(工作表1!Z$3:Z$195<98%)*(LOOKUP(ROW(工作表1!G$3:G$195),ROW(工作表1!G$3:G$195)/(工作表1!G$3:G$195<>""),工作表1!G$3:G$195)>=TODAY())) -> 3 | I38: =SUMPRODUCT((工作表1!B$3:B$195="MA")*(工作表1!Z$3:Z$195>=97%)*(工作表1!Z$3:Z$195<98%)*(LOOKUP(ROW(工作表1!G$3:G$195),ROW(工作表1!G$3:G$195)/(工作表1!G$3:G$195<>""),工作表1!G$3:G$195)>=TODAY())) -> 0 | J38: =SUMPRODUCT((工作表1!B$3:B$195="SA")*(工作表1!Z$3:Z$195>=97%)*(工作表1!Z$3:Z$195<98%)*(LOOKUP(ROW(工作表1!G$3:G$195),ROW(工作表1!G$3:G$195)/(工作表1!G$3:G$195<>""),工作表1!G$3:G$195)>=TODAY())) -> 1 | K38: =SUMPRODUCT((工作表1!B$3:B$195="VRV")*(工作表1!Z$3:Z$195>=97%)*(工作表1!Z$3:Z$195<98%)*(LOOKUP(ROW(工作表1!G$3:G$195),ROW(工作表1!G$3:G$195)/(工作表1!G$3:G$195<>""),工作表1!G$3:G$195)>=TODAY())) -> 4
G39: 98% | H39: =SUMPRODUCT((工作表1!B$3:B$195="RA")*(工作表1!Z$3:Z$195>=98%)*(工作表1!Z$3:Z$195<99%)*(LOOKUP(ROW(工作表1!G$3:G$195),ROW(工作表1!G$3:G$195)/(工作表1!G$3:G$195<>""),工作表1!G$3:G$195)>=TODAY())) -> 6 | I39: =SUMPRODUCT((工作表1!B$3:B$195="MA")*(工作表1!Z$3:Z$195>=98%)*(工作表1!Z$3:Z$195<99%)*(LOOKUP(ROW(工作表1!G$3:G$195),ROW(工作表1!G$3:G$195)/(工作表1!G$3:G$195<>""),工作表1!G$3:G$195)>=TODAY())) -> 0 | J39: =SUMPRODUCT((工作表1!B$3:B$195="SA")*(工作表1!Z$3:Z$195>=98%)*(工作表1!Z$3:Z$195<99%)*(LOOKUP(ROW(工作表1!G$3:G$195),ROW(工作表1!G$3:G$195)/(工作表1!G$3:G$195<>""),工作表1!G$3:G$195)>=TODAY())) -> 2 | K39: =SUMPRODUCT((工作表1!B$3:B$195="VRV")*(工作表1!Z$3:Z$195>=98%)*(工作表1!Z$3:Z$195<99%)*(LOOKUP(ROW(工作表1!G$3:G$195),ROW(工作表1!G$3:G$195)/(工作表1!G$3:G$195<>""),工作表1!G$3:G$195)>=TODAY())) -> 5
G40: 99% | H40: =SUMPRODUCT((工作表1!B$3:B$195="RA")*(工作表1!Z$3:Z$195>=99%)*(工作表1!Z$3:Z$195<100%)*(LOOKUP(ROW(工作表1!G$3:G$195),ROW(工作表1!G$3:G$195)/(工作表1!G$3:G$195<>""),工作表1!G$3:G$195)>=TODAY())) -> 4 | I40: =SUMPRODUCT((工作表1!B$3:B$195="MA")*(工作表1!Z$3:Z$195>=99%)*(工作表1!Z$3:Z$195<100%)*(LOOKUP(ROW(工作表1!G$3:G$195),ROW(工作表1!G$3:G$195)/(工作表1!G$3:G$195<>""),工作表1!G$3:G$195)>=TODAY())) -> 0 | J40: =SUMPRODUCT((工作表1!B$3:B$195="SA")*(工作表1!Z$3:Z$195>=99%)*(工作表1!Z$3:Z$195<100%)*(LOOKUP(ROW(工作表1!G$3:G$195),ROW(工作表1!G$3:G$195)/(工作表1!G$3:G$195<>""),工作表1!G$3:G$195)>=TODAY())) -> 2 | K40: =SUMPRODUCT((工作表1!B$3:B$195="VRV")*(工作表1!Z$3:Z$195>=99%)*(工作表1!Z$3:Z$195<100%)*(LOOKUP(ROW(工作表1!G$3:G$195),ROW(工作表1!G$3:G$195)/(工作表1!G$3:G$195<>""),工作表1!G$3:G$195)>=TODAY())) -> 1
G41: 100% | H41: =SUMPRODUCT((工作表1!B$3:B$195="RA")*(工作表1!Z$3:Z$195>=100%)*(工作表1!Z$3:Z$195<101%)*(LOOKUP(ROW(工作表1!G$3:G$195),ROW(工作表1!G$3:G$195)/(工作表1!G$3:G$195<>""),工作表1!G$3:G$195)>=TODAY())) -> 5 | I41: =SUMPRODUCT((工作表1!B$3:B$195="MA")*(工作表1!Z$3:Z$195>=100%)*(工作表1!Z$3:Z$195<101%)*(LOOKUP(ROW(工作表1!G$3:G$195),ROW(工作表1!G$3:G$195)/(工作表1!G$3:G$195<>""),工作表1!G$3:G$195)>=TODAY())) -> 3 | J41: =SUMPRODUCT((工作表1!B$3:B$195="SA")*(工作表1!Z$3:Z$195>=100%)*(工作表1!Z$3:Z$195<101%)*(LOOKUP(ROW(工作表1!G$3:G$195),ROW(工作表1!G$3:G$195)/(工作表1!G$3:G$195<>""),工作表1!G$3:G$195)>=TODAY())) -> 2 | K41: =SUMPRODUCT((工作表1!B$3:B$195="VRV")*(工作表1!Z$3:Z$195>=100%)*(工作表1!Z$3:Z$195<101%)*(LOOKUP(ROW(工作表1!G$3:G$195),ROW(工作表1!G$3:G$195)/(工作表1!G$3:G$195<>""),工作表1!G$3:G$195)>=TODAY())) -> 2
G42: 101% | H42: =SUMPRODUCT((工作表1!B$3:B$195="RA")*(工作表1!Z$3:Z$195>=101%)*(工作表1!Z$3:Z$195<102%)*(LOOKUP(ROW(工作表1!G$3:G$195),ROW(工作表1!G$3:G$195)/(工作表1!G$3:G$195<>""),工作表1!G$3:G$195)>=TODAY())) -> 4 | I42: =SUMPRODUCT((工作表1!B$3:B$195="MA")*(工作表1!Z$3:Z$195>=101%)*(工作表1!Z$3:Z$195<102%)*(LOOKUP(ROW(工作表1!G$3:G$195),ROW(工作表1!G$3:G$195)/(工作表1!G$3:G$195<>""),工作表1!G$3:G$195)>=TODAY())) -> 2 | J42: =SUMPRODUCT((工作表1!B$3:B$195="SA")*(工作表1!Z$3:Z$195>=101%)*(工作表1!Z$3:Z$195<102%)*(LOOKUP(ROW(工作表1!G$3:G$195),ROW(工作表1!G$3:G$195)/(工作表1!G$3:G$195<>""),工作表1!G$3:G$195)>=TODAY())) -> 4 | K42: =SUMPRODUCT((工作表1!B$3:B$195="VRV")*(工作表1!Z$3:Z$195>=101%)*(工作表1!Z$3:Z$195<102%)*(LOOKUP(ROW(工作表1!G$3:G$195),ROW(工作表1!G$3:G$195)/(工作表1!G$3:G$195<>""),工作表1!G$3:G$195)>=TODAY())) -> 0
G43: 102% | H43: =SUMPRODUCT((工作表1!B$3:B$195="RA")*(工作表1!Z$3:Z$195>=102%)*(工作表1!Z$3:Z$195<103%)*(LOOKUP(ROW(工作表1!G$3:G$195),ROW(工作表1!G$3:G$195)/(工作表1!G$3:G$195<>""),工作表1!G$3:G$195)>=TODAY())) -> 2 | I43: =SUMPRODUCT((工作表1!B$3:B$195="MA")*(工作表1!Z$3:Z$195>=102%)*(工作表1!Z$3:Z$195<103%)*(LOOKUP(ROW(工作表1!G$3:G$195),ROW(工作表1!G$3:G$195)/(工作表1!G$3:G$195<>""),工作表1!G$3:G$195)>=TODAY())) -> 1 | J43: =SUMPRODUCT((工作表1!B$3:B$195="SA")*(工作表1!Z$3:Z$195>=102%)*(工作表1!Z$3:Z$195<103%)*(LOOKUP(ROW(工作表1!G$3:G$195),ROW(工作表1!G$3:G$195)/(工作表1!G$3:G$195<>""),工作表1!G$3:G$195)>=TODAY())) -> 0 | K43: =SUMPRODUCT((工作表1!B$3:B$195="VRV")*(工作表1!Z$3:Z$195>=102%)*(工作表1!Z$3:Z$195<103%)*(LOOKUP(ROW(工作表1!G$3:G$195),ROW(工作表1!G$3:G$195)/(工作表1!G$3:G$195<>""),工作表1!G$3:G$195)>=TODAY())) -> 0
G44: 103% | H44: =SUMPRODUCT((工作表1!B$3:B$195="RA")*(工作表1!Z$3:Z$195>=103%)*(工作表1!Z$3:Z$195<104%)*(LOOKUP(ROW(工作表1!G$3:G$195),ROW(工作表1!G$3:G$195)/(工作表1!G$3:G$195<>""),工作表1!G$3:G$195)>=TODAY())) -> 5 | I44: =SUMPRODUCT((工作表1!B$3:B$195="MA")*(工作表1!Z$3:Z$195>=103%)*(工作表1!Z$3:Z$195<104%)*(LOOKUP(ROW(工作表1!G$3:G$195),ROW(工作表1!G$3:G$195)/(工作表1!G$3:G$195<>""),工作表1!G$3:G$195)>=TODAY())) -> 4 | J44: =SUMPRODUCT((工作表1!B$3:B$195="SA")*(工作表1!Z$3:Z$195>=103%)*(工作表1!Z$3:Z$195<104%)*(LOOKUP(ROW(工作表1!G$3:G$195),ROW(工作表1!G$3:G$195)/(工作表1!G$3:G$195<>""),工作表1!G$3:G$195)>=TODAY())) -> 3 | K44: =SUMPRODUCT((工作表1!B$3:B$195="VRV")*(工作表1!Z$3:Z$195>=103%)*(工作表1!Z$3:Z$195<104%)*(LOOKUP(ROW(工作表1!G$3:G$195),ROW(工作表1!G$3:G$195)/(工作表1!G$3:G$195<>""),工作表1!G$3:G$195)>=TODAY())) -> 0
...
